Workbook

Sheet Summary
A1: Account ID | B1: Account Name | C1: Demand Submission Status | F1: Laptop Delivery Status
C2: Total Demand | D2: Already in Master list | E2: Pending to be added | F2: Delivered | G2: Delivery in Progress | H2: Delivery constraints | I2: Not Scheduled for Delivery
A3: 1203971 | B3: CCC Information Services | C3: =COUNTIFS('Master Request'!A:A,A3) -> 124 | D3: =COUNTIFS('Master Request'!A:A,A3,'Master Request'!G:G,"Yes") -> 55 | E3: =C3-D3 -> 69 | F3: =COUNTIFS('Master Request'!A:A,A3,'Master Request'!H:H,F$2) -> 0 | G3: =COUNTIFS('Master Request'!A:A,A3,'Master Request'!H:H,G$2) -> 10 | H3: =COUNTIFS('Master Request'!A:A,A3,'Master Request'!H:H,H$2) -> 0 | I3: =COUNTIFS('Master Request'!A:A,A3,'Master Request'!H:H,I$2) -> 114
A4: 1202752 | B4: Great American Fincl Resources | C4: =COUNTIFS('Master Request'!A:A,A4) -> 0 | D4: =COUNTIFS('Master Request'!A:A,A4,'Master Request'!G:G,"Yes") -> 0 | E4: =C4-D4 -> 0 | F4: =COUNTIFS('Master Request'!A:A,A4,'Master Request'!H:H,F$2) -> 0 | G4: =COUNTIFS('Master Request'!A:A,A4,'Master Request'!H:H,G$2) -> 0 | H4: =COUNTIFS('Master Request'!A:A,A4,'Master Request'!H:H,H$2) -> 0 | I4: =COUNTIFS('Master Request'!A:A,A4,'Master Request'!H:H,I$2) -> 0
A5: 1211720 | B5: Motorists Mutual Insurance Company | C5: =COUNTIFS('Master Request'!A:A,A5) -> 0 | D5: =COUNTIFS('Master Request'!A:A,A5,'Master Request'!G:G,"Yes") -> 0 | E5: =C5-D5 -> 0 | F5: =COUNTIFS('Master Request'!A:A,A5,'Master Request'!H:H,F$2) -> 0 | G5: =COUNTIFS('Master Request'!A:A,A5,'Master Request'!H:H,G$2) -> 0 | H5: =COUNTIFS('Master Request'!A:A,A5,'Master Request'!H:H,H$2) -> 0 | I5: =COUNTIFS('Master Request'!A:A,A5,'Master Request'!H:H,I$2) -> 0
A6: 1202811 | B6: State Auto Financial Corp | C6: =COUNTIFS('Master Request'!A:A,A6) -> 0 | D6: =COUNTIFS('Master Request'!A:A,A6,'Master Request'!G:G,"Yes") -> 0 | E6: =C6-D6 -> 0 | F6: =COUNTIFS('Master Request'!A:A,A6,'Master Request'!H:H,F$2) -> 0 | G6: =COUNTIFS('Master Request'!A:A,A6,'Master Request'!H:H,G$2) -> 0 | H6: =COUNTIFS('Master Request'!A:A,A6,'Master Request'!H:H,H$2) -> 0 | I6: =COUNTIFS('Master Request'!A:A,A6,'Master Request'!H:H,I$2) -> 0

Sheet Sheet1
A3: Count of Associate Full Name | B3: Column Labels
A4: Row Labels | B4: Cognizant desktop | C4: Cognizant laptop | D4: Not Enabled | E4: Personal laptops | F4: #N/A | G4: Grand Total
A5: CCC ITIS Infra Support | C5: 2 | E5: 32 | G5: 34
A6: CCC Products Testing | C6: 1 | E6: 16 | G6: 17
A7: CCC Workflow App Maintenance | C7: 1 | E7: 10 | G7: 11
A8: CCC Comparable Database | B8: 2 | D8: 3 | E8: 10 | G8: 15
A9: CCC OMC Support – IT IS | E9: 9 | G9: 9
A10: CCC Inf-Vantive-DEC 2019 | C10: 1 | E10: 8 | G10: 9
A11: CCC BI Support | C11: 1 | E11: 6 | G11: 7
A12: CCC VIN BPO | D12: 1 | E12: 4 | G12: 5
A13: CCC Inf-Casualty Testing,Data | C13: 1 | E13: 4 | G13: 5
A14: CCC - AIS - App & System Supp | C14: 1 | E14: 4 | G14: 5
A15: Production Support&Maintenance | C15: 3 | E15: 2 | G15: 5
A16: CCC Inf-Salesforce-JAN 2020 | E16: 1 | G16: 1
A17: #N/A | F17: 1 | G17: 1
A18: Grand Total | B18: 2 | C18: 11 | D18: 4 | E18: 106 | F18: 1 | G18: 124

Sheet Master Request
A1: Acount ID | B1: Account Name | C1: Emp ID | D1: Associate Full Name | E1: Demand Base | F1: Already has Cognizant asset | G1: In Master List | H1: Delivery Status | I1: Lookup from Master file | J1: device | K1: Validated | L1: Project
A2: 1203971 | B2: CCC Information Services Inc. | C2: 146813 | D2: Mohan,Sreevidyaa | E2: Batch 29 | F2: Yes | G2: =IF(LEFT(E2,5)="Batch","Yes","No") -> Yes | H2: =IFERROR(VLOOKUP(C2,'Delivery Status'!$F:$O,10,FALSE),"Not Scheduled for Delivery") -> Delivery in Progress | I2: =IFERROR(VLOOKUP(C2,[1]Master!$L:$AN,29,FALSE),"") -> Batch 29 | J2: =VLOOKUP(C2,'[2]CCC Coverage base data'!$H:$M,6,FALSE) -> Cognizant laptop | L2: =VLOOKUP(C2,'[2]CCC Coverage base data'!$H:$R,11,FALSE) -> CCC BI Support
A3: 1203971 | B3: CCC Information Services Inc. | C3: 215004 | D3: Mohan,Rathina Jayaram | E3: Batch 29 | F3: Yes | G3: =IF(LEFT(E3,5)="Batch","Yes","No") -> Yes | H3: =IFERROR(VLOOKUP(C3,'Delivery Status'!$F:$O,10,FALSE),"Not Scheduled for Delivery") -> Delivery in Progress | I3: =VLOOKUP(C3,[1]Master!$L:$AN,29,FALSE) -> Batch 29 | J3: =VLOOKUP(C3,'[2]CCC Coverage base data'!$H:$M,6,FALSE) -> Cognizant laptop | L3: =VLOOKUP(C3,'[2]CCC Coverage base data'!$H:$R,11,FALSE) -> CCC - AIS - App & System Supp
A4: 1203971 | B4: CCC Information Services Inc. | C4: 273219 | D4: B,Thiagarajan | E4: Batch 29 | G4: =IF(LEFT(E4,5)="Batch","Yes","No") -> Yes | H4: =IFERROR(VLOOKUP(C4,'Delivery Status'!$F:$O,10,FALSE),"Not Scheduled for Delivery") -> Not Scheduled for Delivery | I4: =VLOOKUP(C4,[1]Master!$L:$AN,29,FALSE) -> Batch 29 | J4: =VLOOKUP(C4,'[2]CCC Coverage base data'!$H:$M,6,FALSE) -> Personal laptops | L4: =VLOOKUP(C4,'[2]CCC Coverage base data'!$H:$R,11,FALSE) -> CCC ITIS Infra Support
A5: 1203971 | B5: CCC Information Services Inc. | C5: 279828 | D5: S,Arivazhagan | E5: Batch 29 | G5: =IF(LEFT(E5,5)="Batch","Yes","No") -> Yes | H5: =IFERROR(VLOOKUP(C5,'Delivery Status'!$F:$O,10,FALSE),"Not Scheduled for Delivery") -> Not Scheduled for Delivery | I5: =VLOOKUP(C5,[1]Master!$L:$AN,29,FALSE) -> Batch 29 | J5: =VLOOKUP(C5,'[2]CCC Coverage base data'!$H:$M,6,FALSE) -> Not Enabled | L5: =VLOOKUP(C5,'[2]CCC Coverage base data'!$H:$R,11,FALSE) -> CCC VIN BPO
A6: 1203971 | B6: CCC Information Services Inc. | C6: 304623 | D6: Thavasiappan,Nithianandam | E6: Batch 29 | G6: =IF(LEFT(E6,5)="Batch","Yes","No") -> Yes | H6: =IFERROR(VLOOKUP(C6,'Delivery Status'!$F:$O,10,FALSE),"Not Scheduled for Delivery") -> Not Scheduled for Delivery | I6: =VLOOKUP(C6,[1]Master!$L:$AN,29,FALSE) -> Batch 29 | J6: =VLOOKUP(C6,'[2]CCC Coverage base data'!$H:$M,6,FALSE) -> Personal laptops | L6: =VLOOKUP(C6,'[2]CCC Coverage base data'!$H:$R,11,FALSE) -> CCC - AIS - App & System Supp
A7: 1203971 | B7: CCC Information Services Inc. | C7: 312657 | D7: Radhakrishnan,Ranjit | E7: Batch 29 | G7: =IF(LEFT(E7,5)="Batch","Yes","No") -> Yes | H7: =IFERROR(VLOOKUP(C7,'Delivery Status'!$F:$O,10,FALSE),"Not Scheduled for Delivery") -> Not Scheduled for Delivery | I7: =VLOOKUP(C7,[1]Master!$L:$AN,29,FALSE) -> Batch 29 | J7: =VLOOKUP(C7,'[2]CCC Coverage base data'!$H:$M,6,FALSE) -> Personal laptops | L7: =VLOOKUP(C7,'[2]CCC Coverage base data'!$H:$R,11,FALSE) -> CCC Comparable Database
A8: 1203971 | B8: CCC Information Services Inc. | C8: 348305 | D8: K,Vinod Kumar | E8: Batch 29 | G8: =IF(LEFT(E8,5)="Batch","Yes","No") -> Yes | H8: =IFERROR(VLOOKUP(C8,'Delivery Status'!$F:$O,10,FALSE),"Not Scheduled for Delivery") -> Not Scheduled for Delivery | I8: =VLOOKUP(C8,[1]Master!$L:$AN,29,FALSE) -> Batch 29 | J8: =VLOOKUP(C8,'[2]CCC Coverage base data'!$H:$M,6,FALSE) -> Personal laptops | L8: =VLOOKUP(C8,'[2]CCC Coverage base data'!$H:$R,11,FALSE) -> CCC ITIS Infra Support
A9: 1203971 | B9: CCC Information Services Inc. | C9: 573501 | D9: Duggineni,Srikanth | E9: Batch 29 | G9: =IF(LEFT(E9,5)="Batch","Yes","No") -> Yes | H9: =IFERROR(VLOOKUP(C9,'Delivery Status'!$F:$O,10,FALSE),"Not Scheduled for Delivery") -> Not Scheduled for Delivery | I9: =VLOOKUP(C9,[1]Master!$L:$AN,29,FALSE) -> Batch 29 | J9: =VLOOKUP(C9,'[2]CCC Coverage base data'!$H:$M,6,FALSE) -> Personal laptops | L9: =VLOOKUP(C9,'[2]CCC Coverage base data'!$H:$R,11,FALSE) -> CCC ITIS Infra Support
A10: 1203971 | B10: CCC Information Services Inc. | C10: 574369 | D10: Balan,Ganesh | E10: Batch 29 | F10: Yes | G10: =IF(LEFT(E10,5)="Batch","Yes","No") -> Yes | H10: =IFERROR(VLOOKUP(C10,'Delivery Status'!$F:$O,10,FALSE),"Not Scheduled for Delivery") -> Delivery in Progress | I10: =VLOOKUP(C10,[1]Master!$L:$AN,29,FALSE) -> Batch 29 | J10: =VLOOKUP(C10,'[2]CCC Coverage base data'!$H:$M,6,FALSE) -> Cognizant laptop | L10: =VLOOKUP(C10,'[2]CCC Coverage base data'!$H:$R,11,FALSE) -> Production Support&Maintenance
A11: 1203971 | B11: CCC Information Services Inc. | C11: 578914 | D11: R,Ganesh | E11: Batch 29 | G11: =IF(LEFT(E11,5)="Batch","Yes","No") -> Yes | H11: =IFERROR(VLOOKUP(C11,'Delivery Status'!$F:$O,10,FALSE),"Not Scheduled for Delivery") -> Not Scheduled for Delivery | I11: =VLOOKUP(C11,[1]Master!$L:$AN,29,FALSE) -> Batch 29 | J11: =VLOOKUP(C11,'[2]CCC Coverage base data'!$H:$M,6,FALSE) -> Personal laptops | L11: =VLOOKUP(C11,'[2]CCC Coverage base data'!$H:$R,11,FALSE) -> CCC OMC Support – IT IS
A12: 1203971 | B12: CCC Information Services Inc. | C12: 592383 | D12: Ganesan,Eashwar | E12: Batch 29 | G12: =IF(LEFT(E12,5)="Batch","Yes","No") -> Yes | H12: =IFERROR(VLOOKUP(C12,'Delivery Status'!$F:$O,10,FALSE),"Not Scheduled for Delivery") -> Not Scheduled for Delivery | I12: =VLOOKUP(C12,[1]Master!$L:$AN,29,FALSE) -> Batch 29 | J12: =VLOOKUP(C12,'[2]CCC Coverage base data'!$H:$M,6,FALSE) -> Personal laptops | L12: =VLOOKUP(C12,'[2]CCC Coverage base data'!$H:$R,11,FALSE) -> Production Support&Maintenance
A13: 1203971 | B13: CCC Information Services Inc. | C13: 606437 | D13: Swarna,Sreenivasulu | E13: Batch 29 | F13: Yes | G13: =IF(LEFT(E13,5)="Batch","Yes","No") -> Yes | H13: =IFERROR(VLOOKUP(C13,'Delivery Status'!$F:$O,10,FALSE),"Not Scheduled for Delivery") -> Delivery in Progress | I13: =VLOOKUP(C13,[1]Master!$L:$AN,29,FALSE) -> Batch 29 | J13: =VLOOKUP(C13,'[2]CCC Coverage base data'!$H:$M,6,FALSE) -> Cognizant laptop | L13: =VLOOKUP(C13,'[2]CCC Coverage base data'!$H:$R,11,FALSE) -> CCC Workflow App Maintenance
A14: 1203971 | B14: CCC Information Services Inc. | C14: 611826 | D14: PG,Aneesh | E14: Batch 29 | G14: =IF(LEFT(E14,5)="Batch","Yes","No") -> Yes | H14: =IFERROR(VLOOKUP(C14,'Delivery Status'!$F:$O,10,FALSE),"Not Scheduled for Delivery") -> Not Scheduled for Delivery | I14: =VLOOKUP(C14,[1]Master!$L:$AN,29,FALSE) -> Batch 29 | J14: =VLOOKUP(C14,'[2]CCC Coverage base data'!$H:$M,6,FALSE) -> Personal laptops | L14: =VLOOKUP(C14,'[2]CCC Coverage base data'!$H:$R,11,FALSE) -> CCC Workflow App Maintenance
A15: 1203971 | B15: CCC Information Services Inc. | C15: 668397 | D15: Arunachalam,Parvathi | E15: Batch 29 | G15: =IF(LEFT(E15,5)="Batch","Yes","No") -> Yes | H15: =IFERROR(VLOOKUP(C15,'Delivery Status'!$F:$O,10,FALSE),"Not Scheduled for Delivery") -> Not Scheduled for Delivery | I15: =VLOOKUP(C15,[1]Master!$L:$AN,29,FALSE) -> Batch 29 | J15: =VLOOKUP(C15,'[2]CCC Coverage base data'!$H:$M,6,FALSE) -> Personal laptops | L15: =VLOOKUP(C15,'[2]CCC Coverage base data'!$H:$R,11,FALSE) -> CCC - AIS - App & System Supp
A16: 1203971 | B16: CCC Information Services Inc. | C16: 669127 | D16: K,Hariprasad | E16: Batch 29 | G16: =IF(LEFT(E16,5)="Batch","Yes","No") -> Yes | H16: =IFERROR(VLOOKUP(C16,'Delivery Status'!$F:$O,10,FALSE),"Not Scheduled for Delivery") -> Not Scheduled for Delivery | I16: =VLOOKUP(C16,[1]Master!$L:$AN,29,FALSE) -> Batch 29 | J16: =VLOOKUP(C16,'[2]CCC Coverage base data'!$H:$M,6,FALSE) -> Personal laptops | L16: =VLOOKUP(C16,'[2]CCC Coverage base data'!$H:$R,11,FALSE) -> CCC BI Support
A17: 1203971 | B17: CCC Information Services Inc. | C17: 671609 | D17: P,Praveen Kumar | E17: Batch 29 | G17: =IF(LEFT(E17,5)="Batch","Yes","No") -> Yes | H17: =IFERROR(VLOOKUP(C17,'Delivery Status'!$F:$O,10,FALSE),"Not Scheduled for Delivery") -> Not Scheduled for Delivery | I17: =VLOOKUP(C17,[1]Master!$L:$AN,29,FALSE) -> Batch 29 | J17: =VLOOKUP(C17,'[2]CCC Coverage base data'!$H:$M,6,FALSE) -> Personal laptops | L17: =VLOOKUP(C17,'[2]CCC Coverage base data'!$H:$R,11,FALSE) -> CCC ITIS Infra Support
A18: 1203971 | B18: CCC Information Services Inc. | C18: 678596 | D18: Gopalsamy,Prabaharan | E18: Batch 29 | G18: =IF(LEFT(E18,5)="Batch","Yes","No") -> Yes | H18: =IFERROR(VLOOKUP(C18,'Delivery Status'!$F:$O,10,FALSE),"Not Scheduled for Delivery") -> Not Scheduled for Delivery | I18: =VLOOKUP(C18,[1]Master!$L:$AN,29,FALSE) -> Batch 29 | J18: =VLOOKUP(C18,'[2]CCC Coverage base data'!$H:$M,6,FALSE) -> Personal laptops | L18: =VLOOKUP(C18,'[2]CCC Coverage base data'!$H:$R,11,FALSE) -> CCC ITIS Infra Support
A19: 1203971 | B19: CCC Information Services Inc. | C19: 679500 | D19: Venkatachari,Aswinkumar | E19: Batch 29 | G19: =IF(LEFT(E19,5)="Batch","Yes","No") -> Yes | H19: =IFERROR(VLOOKUP(C19,'Delivery Status'!$F:$O,10,FALSE),"Not Scheduled for Delivery") -> Not Scheduled for Delivery | I19: =VLOOKUP(C19,[1]Master!$L:$AN,29,FALSE) -> Batch 29 | J19: =VLOOKUP(C19,'[2]CCC Coverage base data'!$H:$M,6,FALSE) -> Personal laptops | L19: =VLOOKUP(C19,'[2]CCC Coverage base data'!$H:$R,11,FALSE) -> CCC ITIS Infra Support
A20: 1203971 | B20: CCC Information Services Inc. | C20: 680179 | D20: S,Muralidharan | E20: Batch 29 | G20: =IF(LEFT(E20,5)="Batch","Yes","No") -> Yes | H20: =IFERROR(VLOOKUP(C20,'Delivery Status'!$F:$O,10,FALSE),"Not Scheduled for Delivery") -> Not Scheduled for Delivery | I20: =VLOOKUP(C20,[1]Master!$L:$AN,29,FALSE) -> Batch 29 | J20: =VLOOKUP(C20,'[2]CCC Coverage base data'!$H:$M,6,FALSE) -> Personal laptops | L20: =VLOOKUP(C20,'[2]CCC Coverage base data'!$H:$R,11,FALSE) -> CCC ITIS Infra Support
A21: 1203971 | B21: CCC Information Services Inc. | C21: 686535 | D21: N.P,Vignesh | E21: Batch 29 | G21: =IF(LEFT(E21,5)="Batch","Yes","No") -> Yes | H21: =IFERROR(VLOOKUP(C21,'Delivery Status'!$F:$O,10,FALSE),"Not Scheduled for Delivery") -> Not Scheduled for Delivery | I21: =VLOOKUP(C21,[1]Master!$L:$AN,29,FALSE) -> Batch 29 | J21: =VLOOKUP(C21,'[2]CCC Coverage base data'!$H:$M,6,FALSE) -> Personal laptops | L21: =VLOOKUP(C21,'[2]CCC Coverage base data'!$H:$R,11,FALSE) -> CCC ITIS Infra Support
A22: 1203971 | B22: CCC Information Services Inc. | C22: 690632 | D22: A,Antony Nirmal | E22: Batch 29 | G22: =IF(LEFT(E22,5)="Batch","Yes","No") -> Yes | H22: =IFERROR(VLOOKUP(C22,'Delivery Status'!$F:$O,10,FALSE),"Not Scheduled for Delivery") -> Not Scheduled for Delivery | I22: =VLOOKUP(C22,[1]Master!$L:$AN,29,FALSE) -> Batch 29 | J22: =VLOOKUP(C22,'[2]CCC Coverage base data'!$H:$M,6,FALSE) -> Personal laptops | L22: =VLOOKUP(C22,'[2]CCC Coverage base data'!$H:$R,11,FALSE) -> CCC - AIS - App & System Supp
A23: 1203971 | B23: CCC Information Services Inc. | C23: 698420 | D23: Periyasamy,Satheesh Kumar | E23: Batch 29 | G23: =IF(LEFT(E23,5)="Batch","Yes","No") -> Yes | H23: =IFERROR(VLOOKUP(C23,'Delivery Status'!$F:$O,10,FALSE),"Not Scheduled for Delivery") -> Not Scheduled for Delivery | I23: =VLOOKUP(C23,[1]Master!$L:$AN,29,FALSE) -> Batch 29 | J23: =VLOOKUP(C23,'[2]CCC Coverage base data'!$H:$M,6,FALSE) -> Personal laptops | L23: =VLOOKUP(C23,'[2]CCC Coverage base data'!$H:$R,11,FALSE) -> CCC - AIS - App & System Supp
A24: 1203971 | B24: CCC Information Services Inc. | C24: 699859 | D24: A L,Gurumoorthy | E24: Batch 29 | G24: =IF(LEFT(E24,5)="Batch","Yes","No") -> Yes | H24: =IFERROR(VLOOKUP(C24,'Delivery Status'!$F:$O,10,FALSE),"Not Scheduled for Delivery") -> Not Scheduled for Delivery | I24: =VLOOKUP(C24,[1]Master!$L:$AN,29,FALSE) -> Batch 29 | J24: =VLOOKUP(C24,'[2]CCC Coverage base data'!$H:$M,6,FALSE) -> Personal laptops | L24: =VLOOKUP(C24,'[2]CCC Coverage base data'!$H:$R,11,FALSE) -> CCC ITIS Infra Support
A25: 1203971 | B25: CCC Information Services Inc. | C25: 701663 | D25: Settipalli,Lohith Reddy | E25: Batch 29 | G25: =IF(LEFT(E25,5)="Batch","Yes","No") -> Yes | H25: =IFERROR(VLOOKUP(C25,'Delivery Status'!$F:$O,10,FALSE),"Not Scheduled for Delivery") -> Not Scheduled for Delivery | I25: =VLOOKUP(C25,[1]Master!$L:$AN,29,FALSE) -> Batch 29 | J25: =VLOOKUP(C25,'[2]CCC Coverage base data'!$H:$M,6,FALSE) -> Personal laptops | L25: =VLOOKUP(C25,'[2]CCC Coverage base data'!$H:$R,11,FALSE) -> CCC Inf-Vantive-DEC 2019
A26: 1203971 | B26: CCC Information Services Inc. | C26: 715081 | D26: Sivachandra,Kongara | E26: Batch 29 | G26: =IF(LEFT(E26,5)="Batch","Yes","No") -> Yes | H26: =IFERROR(VLOOKUP(C26,'Delivery Status'!$F:$O,10,FALSE),"Not Scheduled for Delivery") -> Not Scheduled for Delivery | I26: =VLOOKUP(C26,[1]Master!$L:$AN,29,FALSE) -> Batch 29 | J26: =VLOOKUP(C26,'[2]CCC Coverage base data'!$H:$M,6,FALSE) -> Personal laptops | L26: =VLOOKUP(C26,'[2]CCC Coverage base data'!$H:$R,11,FALSE) -> CCC Workflow App Maintenance
A27: 1203971 | B27: CCC Information Services Inc. | C27: 717007 | D27: Bhaskaran,Priyadharsine | E27: Batch 29 | F27: Yes | G27: =IF(LEFT(E27,5)="Batch","Yes","No") -> Yes | H27: =IFERROR(VLOOKUP(C27,'Delivery Status'!$F:$O,10,FALSE),"Not Scheduled for Delivery") -> Delivery in Progress | I27: =VLOOKUP(C27,[1]Master!$L:$AN,29,FALSE) -> Batch 29 | J27: =VLOOKUP(C27,'[2]CCC Coverage base data'!$H:$M,6,FALSE) -> Cognizant laptop | K27: Yes | L27: =VLOOKUP(C27,'[2]CCC Coverage base data'!$H:$R,11,FALSE) -> CCC Products Testing
A28: 1203971 | B28: CCC Information Services Inc. | C28: 721890 | D28: Perumal,Praveena | E28: Batch 29 | G28: =IF(LEFT(E28,5)="Batch","Yes","No") -> Yes | H28: =IFERROR(VLOOKUP(C28,'Delivery Status'!$F:$O,10,FALSE),"Not Scheduled for Delivery") -> Not Scheduled for Delivery | I28: =VLOOKUP(C28,[1]Master!$L:$AN,29,FALSE) -> Batch 29 | J28: =VLOOKUP(C28,'[2]CCC Coverage base data'!$H:$M,6,FALSE) -> Personal laptops | L28: =VLOOKUP(C28,'[2]CCC Coverage base data'!$H:$R,11,FALSE) -> CCC OMC Support – IT IS
A29: 1203971 | B29: CCC Information Services Inc. | C29: 723473 | D29: Mohan,Venkatakrishnan | E29: Batch 29 | G29: =IF(LEFT(E29,5)="Batch","Yes","No") -> Yes | H29: =IFERROR(VLOOKUP(C29,'Delivery Status'!$F:$O,10,FALSE),"Not Scheduled for Delivery") -> Not Scheduled for Delivery | I29: =VLOOKUP(C29,[1]Master!$L:$AN,29,FALSE) -> Batch 29 | J29: =VLOOKUP(C29,'[2]CCC Coverage base data'!$H:$M,6,FALSE) -> Personal laptops | L29: =VLOOKUP(C29,'[2]CCC Coverage base data'!$H:$R,11,FALSE) -> CCC ITIS Infra Support
A30: 1203971 | B30: CCC Information Services Inc. | C30: 728692 | D30: R,Lakshmanan | E30: Batch 29 | G30: =IF(LEFT(E30,5)="Batch","Yes","No") -> Yes | H30: =IFERROR(VLOOKUP(C30,'Delivery Status'!$F:$O,10,FALSE),"Not Scheduled for Delivery") -> Not Scheduled for Delivery | I30: =VLOOKUP(C30,[1]Master!$L:$AN,29,FALSE) -> Batch 29 | J30: =VLOOKUP(C30,'[2]CCC Coverage base data'!$H:$M,6,FALSE) -> Personal laptops | L30: =VLOOKUP(C30,'[2]CCC Coverage base data'!$H:$R,11,FALSE) -> Production Support&Maintenance
A31: 1203971 | B31: CCC Information Services Inc. | C31: 740539 | D31: G,Thennarasu | E31: Batch 29 | G31: =IF(LEFT(E31,5)="Batch","Yes","No") -> Yes | H31: =IFERROR(VLOOKUP(C31,'Delivery Status'!$F:$O,10,FALSE),"Not Scheduled for Delivery") -> Not Scheduled for Delivery | I31: =VLOOKUP(C31,[1]Master!$L:$AN,29,FALSE) -> Batch 29 | J31: =VLOOKUP(C31,'[2]CCC Coverage base data'!$H:$M,6,FALSE) -> Personal laptops | L31: =VLOOKUP(C31,'[2]CCC Coverage base data'!$H:$R,11,FALSE) -> CCC OMC Support – IT IS
A32: 1203971 | B32: CCC Information Services Inc. | C32: 743132 | D32: N,Sasikumar | E32: Batch 29 | G32: =IF(LEFT(E32,5)="Batch","Yes","No") -> Yes | H32: =IFERROR(VLOOKUP(C32,'Delivery Status'!$F:$O,10,FALSE),"Not Scheduled for Delivery") -> Not Scheduled for Delivery | I32: =VLOOKUP(C32,[1]Master!$L:$AN,29,FALSE) -> Batch 29 | J32: =VLOOKUP(C32,'[2]CCC Coverage base data'!$H:$M,6,FALSE) -> Personal laptops | L32: =VLOOKUP(C32,'[2]CCC Coverage base data'!$H:$R,11,FALSE) -> CCC ITIS Infra Support
A33: 1203971 | B33: CCC Information Services Inc. | C33: 748151 | D33: P,Sravan Kumar | E33: Batch 29 | G33: =IF(LEFT(E33,5)="Batch","Yes","No") -> Yes | H33: =IFERROR(VLOOKUP(C33,'Delivery Status'!$F:$O,10,FALSE),"Not Scheduled for Delivery") -> Not Scheduled for Delivery | I33: =VLOOKUP(C33,[1]Master!$L:$AN,29,FALSE) -> Batch 29 | J33: =VLOOKUP(C33,'[2]CCC Coverage base data'!$H:$M,6,FALSE) -> Personal laptops | L33: =VLOOKUP(C33,'[2]CCC Coverage base data'!$H:$R,11,FALSE) -> CCC ITIS Infra Support
A34: 1203971 | B34: CCC Information Services Inc. | C34: 755755 | D34: Kamarajan,Karthick | E34: Batch 29 | G34: =IF(LEFT(E34,5)="Batch","Yes","No") -> Yes | H34: =IFERROR(VLOOKUP(C34,'Delivery Status'!$F:$O,10,FALSE),"Not Scheduled for Delivery") -> Not Scheduled for Delivery | I34: =VLOOKUP(C34,[1]Master!$L:$AN,29,FALSE) -> Batch 29 | J34: =VLOOKUP(C34,'[2]CCC Coverage base data'!$H:$M,6,FALSE) -> Personal laptops | L34: =VLOOKUP(C34,'[2]CCC Coverage base data'!$H:$R,11,FALSE) -> CCC BI Support
A35: 1203971 | B35: CCC Information Services Inc. | C35: 757733 | D35: Yekkala,Sriharsha | E35: Batch 29 | G35: =IF(LEFT(E35,5)="Batch","Yes","No") -> Yes | H35: =IFERROR(VLOOKUP(C35,'Delivery Status'!$F:$O,10,FALSE),"Not Scheduled for Delivery") -> Not Scheduled for Delivery | I35: =VLOOKUP(C35,[1]Master!$L:$AN,29,FALSE) -> Batch 29 | J35: =VLOOKUP(C35,'[2]CCC Coverage base data'!$H:$M,6,FALSE) -> Personal laptops | L35: =VLOOKUP(C35,'[2]CCC Coverage base data'!$H:$R,11,FALSE) -> CCC ITIS Infra Support
A36: 1203971 | B36: CCC Information Services Inc. | C36: 761558 | D36: Kandula,Jagadeshwar Reddy | E36: Batch 29 | G36: =IF(LEFT(E36,5)="Batch","Yes","No") -> Yes | H36: =IFERROR(VLOOKUP(C36,'Delivery Status'!$F:$O,10,FALSE),"Not Scheduled for Delivery") -> Not Scheduled for Delivery | I36: =VLOOKUP(C36,[1]Master!$L:$AN,29,FALSE) -> Batch 29 | J36: =VLOOKUP(C36,'[2]CCC Coverage base data'!$H:$M,6,FALSE) -> Personal laptops | L36: =VLOOKUP(C36,'[2]CCC Coverage base data'!$H:$R,11,FALSE) -> CCC Inf-Vantive-DEC 2019
A37: 1203971 | B37: CCC Information Services Inc. | C37: 773670 | D37: M,Vasantharaja | E37: Batch 29 | F37: Yes | G37: =IF(LEFT(E37,5)="Batch","Yes","No") -> Yes | H37: =IFERROR(VLOOKUP(C37,'Delivery Status'!$F:$O,10,FALSE),"Not Scheduled for Delivery") -> Delivery in Progress | I37: =VLOOKUP(C37,[1]Master!$L:$AN,29,FALSE) -> Batch 29 | J37: =VLOOKUP(C37,'[2]CCC Coverage base data'!$H:$M,6,FALSE) -> Cognizant laptop | L37: =VLOOKUP(C37,'[2]CCC Coverage base data'!$H:$R,11,FALSE) -> Production Support&Maintenance
A38: 1203971 | B38: CCC Information Services Inc. | C38: 776904 | D38: Venkatesan,Deepikashri | E38: Batch 29 | G38: =IF(LEFT(E38,5)="Batch","Yes","No") -> Yes | H38: =IFERROR(VLOOKUP(C38,'Delivery Status'!$F:$O,10,FALSE),"Not Scheduled for Delivery") -> Not Scheduled for Delivery | I38: =VLOOKUP(C38,[1]Master!$L:$AN,29,FALSE) -> Batch 29 | J38: =VLOOKUP(C38,'[2]CCC Coverage base data'!$H:$M,6,FALSE) -> Personal laptops | L38: =VLOOKUP(C38,'[2]CCC Coverage base data'!$H:$R,11,FALSE) -> CCC OMC Support – IT IS
A39: 1203971 | B39: CCC Information Services Inc. | C39: 781586 | D39: Mohammad,Althaf Naveezuddin | E39: Batch 29 | G39: =IF(LEFT(E39,5)="Batch","Yes","No") -> Yes | H39: =IFERROR(VLOOKUP(C39,'Delivery Status'!$F:$O,10,FALSE),"Not Scheduled for Delivery") -> Not Scheduled for Delivery | I39: =VLOOKUP(C39,[1]Master!$L:$AN,29,FALSE) -> Batch 29 | J39: =VLOOKUP(C39,'[2]CCC Coverage base data'!$H:$M,6,FALSE) -> Personal laptops | L39: =VLOOKUP(C39,'[2]CCC Coverage base data'!$H:$R,11,FALSE) -> CCC OMC Support – IT IS
A40: 1203971 | B40: CCC Information Services Inc. | C40: 785795 | D40: Basava,Jagadeesh | E40: Batch 29 | F40: Yes | G40: =IF(LEFT(E40,5)="Batch","Yes","No") -> Yes | H40: =IFERROR(VLOOKUP(C40,'Delivery Status'!$F:$O,10,FALSE),"Not Scheduled for Delivery") -> Delivery in Progress | I40: =VLOOKUP(C40,[1]Master!$L:$AN,29,FALSE) -> Batch 29 | J40: =VLOOKUP(C40,'[2]CCC Coverage base data'!$H:$M,6,FALSE) -> Cognizant laptop | L40: =VLOOKUP(C40,'[2]CCC Coverage base data'!$H:$R,11,FALSE) -> CCC Inf-Vantive-DEC 2019
...

Sheet Delivery Status
A1: City | B1: Location | C1: Asset ID | D1: Serial Number | E1: Lot No | F1: Associate ID | G1: Associate Name | H1: Device Type | I1: Dongle | J1: Date | K1: Allocation Type | L1: Allocation Source | M1: PRAM Master | N1: Account | O1: Final Delivery Status
A2: Chennai | B2: CHN - CKC | C2: LTIN202249 | D2: 5CG0153ZZX | E2: 12/25 | F2: 171681 | G2: Kadappan,Kalaivani | H2: Laptop | I2: Yes | J2: 43953 | K2: Manual | L2: Auto Pilot | M2: OOC / B | N2: GREAT AMERICAN FINANCIAL RESOURCES | O2: =IF(M2="Delivered","Delivered",IF(OR(M2="Shipped Await Confirmation",M2="Shipping in Progress"),"Delivery in Progress","Delivery constraints")) -> Delivery constraints
A3: Coimbatore | B3: CBE - CCC | C3: LTIN209218 | D3: 5CG0156KQ4 | E3: 8/159 | F3: 827315 | G3: M,Iswarya | H3: Laptop | I3: Yes | J3: 43953 | K3: Manual | L3: Auto Pilot - OOC | M3: OOC / B | N3: STATE AUTO FINANCIAL | O3: =IF(M3="Delivered","Delivered",IF(OR(M3="Shipped Await Confirmation",M3="Shipping in Progress"),"Delivery in Progress","Delivery constraints")) -> Delivery constraints
A4: Coimbatore | B4: CBE - CCC | C4: LTIN210922 | D4: 5CG014DRCF | E4: 8/184 | F4: 798053 | G4: S N,Kaaviyan | H4: Laptop | I4: Yes | J4: 43953 | K4: Manual | L4: Auto Pilot - OOC | M4: Shipped Await Confirmation | N4: GREAT AMERICAN FINANCIAL RESOURCES | O4: =IF(M4="Delivered","Delivered",IF(OR(M4="Shipped Await Confirmation",M4="Shipping in Progress"),"Delivery in Progress","Delivery constraints")) -> Delivery in Progress
A5: Coimbatore | B5: CBE - CCC | C5: LTIN210887 | D5: 5CG014DT0P | E5: 8/198 | F5: 767461 | G5: Nallasamy,Indhumathi | H5: Laptop | I5: Yes | J5: 43953 | K5: Manual | L5: Auto Pilot - OOC | M5: Shipped Await Confirmation | N5: GREAT AMERICAN FINANCIAL RESOURCES | O5: =IF(M5="Delivered","Delivered",IF(OR(M5="Shipped Await Confirmation",M5="Shipping in Progress"),"Delivery in Progress","Delivery constraints")) -> Delivery in Progress
A6: Coimbatore | B6: CBE - CCC | C6: LTIN210843 | D6: 5CG014DS90 | E6: 9/25 | F6: 674062 | G6: Rajendran,Shobika | H6: Laptop | I6: Yes | J6: 43953 | K6: Manual | L6: Auto Pilot - OOC | M6: Shipped Await Confirmation | N6: GREAT AMERICAN FINANCIAL RESOURCES | O6: =IF(M6="Delivered","Delivered",IF(OR(M6="Shipped Await Confirmation",M6="Shipping in Progress"),"Delivery in Progress","Delivery constraints")) -> Delivery in Progress
A7: Coimbatore | B7: CBE - CCC | C7: LTIN209774 | D7: 5CG0158BWX | E7: 9/66 | F7: 393165 | G7: Chellappan,Kavya | H7: Laptop | I7: Yes | J7: 43953 | K7: Manual | L7: Auto Pilot - OOC | M7: Shipped Await Confirmation | N7: STATE AUTO FINANCIAL | O7: =IF(M7="Delivered","Delivered",IF(OR(M7="Shipped Await Confirmation",M7="Shipping in Progress"),"Delivery in Progress","Delivery constraints")) -> Delivery in Progress
A8: Coimbatore | B8: CBE - CCC | C8: LTIN209662 | D8: 5CG015818V | E8: 9/81 | F8: 193857 | G8: M,Hemalatha | H8: Laptop | I8: Yes | J8: 43953 | K8: Manual | L8: Auto Pilot - OOC | M8: Shipped Await Confirmation | N8: STATE AUTO FINANCIAL | O8: =IF(M8="Delivered","Delivered",IF(OR(M8="Shipped Await Confirmation",M8="Shipping in Progress"),"Delivery in Progress","Delivery constraints")) -> Delivery in Progress
A9: Chennai | B9: CHN - TBM | C9: LTIN185740 | D9: 5CG0148XHP | E9: H10/129 | F9: 806862 | G9: S,Jagadeeshwari | H9: Laptop | I9: Yes | J9: 43953 | K9: Manual | L9: Auto Pilot - OOC | M9: Shipped Await Confirmation | N9: STATE AUTO FINANCIAL | O9: =IF(M9="Delivered","Delivered",IF(OR(M9="Shipped Await Confirmation",M9="Shipping in Progress"),"Delivery in Progress","Delivery constraints")) -> Delivery in Progress
A10: Chennai | B10: CHN - TBM | C10: LTIN185821 | D10: 5CG0148XRL | E10: H10/130 | F10: 806858 | G10: Priya,Sathiya | H10: Laptop | I10: Yes | J10: 43953 | K10: Manual | L10: Auto Pilot - OOC | M10: Shipped Await Confirmation | N10: STATE AUTO FINANCIAL | O10: =IF(M10="Delivered","Delivered",IF(OR(M10="Shipped Await Confirmation",M10="Shipping in Progress"),"Delivery in Progress","Delivery constraints")) -> Delivery in Progress
A11: Chennai | B11: CHN - TBM | C11: LTIN185406 | D11: 5CG0148X55 | E11: H11/8 | F11: 725219 | G11: K,Koothan chinnadurai | H11: Laptop | I11: Yes | J11: 43953 | K11: Manual | L11: Auto Pilot - OOC | M11: Shipped Await Confirmation | N11: GREAT AMERICAN FINANCIAL RESOURCES | O11: =IF(M11="Delivered","Delivered",IF(OR(M11="Shipped Await Confirmation",M11="Shipping in Progress"),"Delivery in Progress","Delivery constraints")) -> Delivery in Progress
A12: Chennai | B12: CHN - TBM | C12: LTIN146494 | D12: 5CG01492N9 | E12: H11/50 | F12: 626516 | G12: Maharaja,Lakshmi Priya | H12: Laptop | I12: Yes | J12: 43953 | K12: Manual | L12: Auto Pilot - OOC | M12: Shipped Await Confirmation | N12: STATE AUTO FINANCIAL | O12: =IF(M12="Delivered","Delivered",IF(OR(M12="Shipped Await Confirmation",M12="Shipping in Progress"),"Delivery in Progress","Delivery constraints")) -> Delivery in Progress
A13: Coimbatore | B13: CBE - CCC | C13: LTIN209552 | D13: 5CG01568N7 | E13: 9/191 | F13: 569477 | G13: Rajendran,Sarigha | H13: Laptop | I13: Yes | J13: 43954 | K13: Manual | L13: Auto Pilot | M13: Shipping In Progress | N13: STATE AUTO FINANCIAL | O13: =IF(M13="Delivered","Delivered",IF(OR(M13="Shipped Await Confirmation",M13="Shipping in Progress"),"Delivery in Progress","Delivery constraints")) -> Delivery in Progress
... A70: Chennai | B70: CHN - CKC | C70: LTIN206758 | D70: 5CG0155V0J | E70: 8/30 | F70: 806025 | G70: Pallapu,Poojitha | H70: Laptop | I70: Yes | J70: 43952 | K70: Manual | L70: Auto Pilot - OOC | M70: Shipping In Progress | N70: Motorists Mutual Insurance Company | O70: =IF(M70="Delivered","Delivered",IF(OR(M70="Shipped Await Confirmation",M70="Shipping in Progress"),"Delivery in Progress","Delivery constraints")) -> Delivery in Progress
A71: 674062
A72: 674487
A73: 685012
A74: 687038
A75: 704837
A76: 708363
A77: 711118
A78: 711980
A79: 713491
A80: 721365
A81: 725219
A82: 729413
... A154: 863717
